<?xml version="1.0" encoding="utf-8"?>
<!-- This URDF was automatically created by SolidWorks to URDF Exporter! Originally created by Stephen Brawner (brawner@gmail.com) 
     Commit Version: 1.6.0-1-g15f4949  Build Version: 1.6.7594.29634
     For more information, please see http://wiki.ros.org/sw_urdf_exporter -->
<robot
  name="agv">
  <link
    name="base_link">
    <inertial>
      <origin
        xyz="0.0505002966767807 0.00340268943530442 0.186954439412333"
        rpy="0 0 0" />
      <mass
        value="17.5299138942342" />
      <inertia
        ixx="0.319961382460128"
        ixy="-0.000296205426794656"
        ixz="-0.00412387234214882"
        iyy="0.338232731422203"
        iyz="0.000136264080457694"
        izz="0.601188341952179" />
    </inertial>
    <visual>
      <origin
        xyz="0 0 0"
        rpy="0 0 0" />
      <geometry>
        <mesh
          filename="package://agv/meshes/base_link.STL" />
      </geometry>
      <material
        name="">
        <color
          rgba="0.752941176470588 0.752941176470588 0.752941176470588 1" />
      </material>
    </visual>
    <collision>
      <origin
        xyz="0 0 0"
        rpy="0 0 0" />
      <geometry>
        <mesh
          filename="package://agv/meshes/base_link.STL" />
      </geometry>
    </collision>
  </link>
  <link
    name="rf_castor">
    <inertial>
      <origin
        xyz="-0.00517721936015575 0.00420937017009781 0.0380494601148337"
        rpy="0 0 0" />
      <mass
        value="0.308413228189857" />
      <inertia
        ixx="0.000176863120144316"
        ixy="-6.36407841398768E-13"
        ixz="6.18013673756808E-06"
        iyy="0.00021986835333067"
        iyz="1.64411145757434E-12"
        izz="0.000225039466115735" />
    </inertial>
    <visual>
      <origin
        xyz="0 0 0"
        rpy="0 0 0" />
      <geometry>
        <mesh
          filename="package://agv/meshes/rf_castor.STL" />
      </geometry>
      <material
        name="">
        <color
          rgba="0.752941176470588 0.752941176470588 0.752941176470588 1" />
      </material>
    </visual>
    <collision>
      <origin
        xyz="0 0 0"
        rpy="0 0 0" />
      <geometry>
        <mesh
          filename="package://agv/meshes/rf_castor.STL" />
      </geometry>
    </collision>
  </link>
  <joint
    name="rf_castor_joint"
    type="continuous">
    <origin
      xyz="0.4437 -0.19935 0.0745"
      rpy="0 0 0" />
    <parent
      link="base_link" />
    <child
      link="rf_castor" />
    <axis
      xyz="0 0 1" />
  </joint>
  <link
    name="rf_wheel">
    <inertial>
      <origin
        xyz="-1.11022302462516E-16 0.00436655577999198 6.66133814775094E-16"
        rpy="0 0 0" />
      <mass
        value="0.626468760963498" />
      <inertia
        ixx="0.000457310851286782"
        ixy="1.15974857117078E-18"
        ixz="2.44835121557937E-19"
        iyy="0.000807704367369126"
        iyz="-1.04383155488073E-20"
        izz="0.000457310851286781" />
    </inertial>
    <visual>
      <origin
        xyz="0 0 0"
        rpy="0 0 0" />
      <geometry>
        <mesh
          filename="package://agv/meshes/rf_wheel.STL" />
      </geometry>
      <material
        name="">
        <color
          rgba="0.898039215686275 0.917647058823529 0.929411764705882 1" />
      </material>
    </visual>
    <collision>
      <origin
        xyz="0 0 0"
        rpy="0 0 0" />
      <geometry>
        <mesh
          filename="package://agv/meshes/rf_wheel.STL" />
      </geometry>
      <surface>
        <friction>
          <ode>
            <mu>0.1</mu>
            <mu2>0.1</mu2>
          </ode>
        </friction>
      </surface>
    </collision>
  </link>
  <joint
    name="rf_wheel_joint"
    type="continuous">
    <origin
      xyz="0.057574 0 -0.024493"
      rpy="0 0 0" />
    <parent
      link="rf_castor" />
    <child
      link="rf_wheel" />
    <axis
      xyz="0 1 0" />
  </joint>
  <link
    name="lf_castor">
    <inertial>
      <origin
        xyz="-0.00517721936966248 0.00420937017066605 0.0380494601034228"
        rpy="0 0 0" />
      <mass
        value="0.308413228261502" />
      <inertia
        ixx="0.000176863120188543"
        ixy="-6.34832873491282E-13"
        ixz="6.18013671363683E-06"
        iyy="0.000219868353385141"
        iyz="1.6494380922632E-12"
        izz="0.000225039466125424" />
    </inertial>
    <visual>
      <origin
        xyz="0 0 0"
        rpy="0 0 0" />
      <geometry>
        <mesh
          filename="package://agv/meshes/lf_castor.STL" />
      </geometry>
      <material
        name="">
        <color
          rgba="0.752941176470588 0.752941176470588 0.752941176470588 1" />
      </material>
    </visual>
    <collision>
      <origin
        xyz="0 0 0"
        rpy="0 0 0" />
      <geometry>
        <mesh
          filename="package://agv/meshes/lf_castor.STL" />
      </geometry>
    </collision>
  </link>
  <joint
    name="lf_castor_joint"
    type="continuous">
    <origin
      xyz="0.4437 0.19062 0.0745"
      rpy="0 0 0" />
    <parent
      link="base_link" />
    <child
      link="lf_castor" />
    <axis
      xyz="0 0 1" />
  </joint>
  <link
    name="lf_wheel">
    <inertial>
      <origin
        xyz="-1.11022302462516E-16 0.00436655577999231 6.66133814775094E-16"
        rpy="0 0 0" />
      <mass
        value="0.626468760963498" />
      <inertia
        ixx="0.000457310851286782"
        ixy="3.7317515145857E-18"
        ixz="3.16889790741702E-19"
        iyy="0.000807704367369126"
        iyz="2.85896953074932E-22"
        izz="0.000457310851286781" />
    </inertial>
    <visual>
      <origin
        xyz="0 0 0"
        rpy="0 0 0" />
      <geometry>
        <mesh
          filename="package://agv/meshes/lf_wheel.STL" />
      </geometry>
      <material
        name="">
        <color
          rgba="0.898039215686275 0.917647058823529 0.929411764705882 1" />
      </material>
    </visual>
    <collision>
      <origin
        xyz="0 0 0"
        rpy="0 0 0" />
      <geometry>
        <mesh
          filename="package://agv/meshes/lf_wheel.STL" />
      </geometry>
       <surface>
        <friction>
          <ode>
            <mu>0.1</mu>
            <mu2>0.1</mu2>
          </ode>
        </friction>
      </surface>
    </collision>
  </link>
  <joint
    name="lf_wheel_joint"
    type="continuous">
    <origin
      xyz="0.057574 0 -0.024493"
      rpy="0 0 0" />
    <parent
      link="lf_castor" />
    <child
      link="lf_wheel" />
    <axis
      xyz="0 1 0" />
  </joint>
  <link
    name="rb_castor">
    <inertial>
      <origin
        xyz="0.00102047268802752 -0.000157185609563959 0.0843331685785828"
        rpy="0 0 0" />
      <mass
        value="0.308413228404139" />
      <inertia
        ixx="0.000176863120342781"
        ixy="-6.35772674730175E-13"
        ixz="6.18013667473174E-06"
        iyy="0.000219868353548994"
        iyz="1.64625950950398E-12"
        izz="0.000225039466135757" />
    </inertial>
    <visual>
      <origin
        xyz="0 0 0"
        rpy="0 0 0" />
      <geometry>
        <mesh
          filename="package://agv/meshes/rb_castor.STL" />
      </geometry>
      <material
        name="">
        <color
          rgba="0.752941176470588 0.752941176470588 0.752941176470588 1" />
      </material>
    </visual>
    <collision>
      <origin
        xyz="0 0 0"
        rpy="0 0 0" />
      <geometry>
        <mesh
          filename="package://agv/meshes/rb_castor.STL" />
      </geometry>
    </collision>
  </link>
  <joint
    name="rb_castor_joint"
    type="continuous">
    <origin
      xyz="-0.35505 -0.19499 0.028216"
      rpy="0 0 0" />
    <parent
      link="base_link" />
    <child
      link="rb_castor" />
    <axis
      xyz="0 0 1" />
  </joint>
  <link
    name="rb_wheel">
    <inertial>
      <origin
        xyz="5.55111512312578E-17 -3.60822483003176E-16 6.86950496486816E-16"
        rpy="0 0 0" />
      <mass
        value="0.626468760963497" />
      <inertia
        ixx="0.000457310851286781"
        ixy="2.59697111503507E-18"
        ixz="-7.58653868681682E-20"
        iyy="0.000807704367369125"
        iyz="1.22078299594063E-18"
        izz="0.00045731085128678" />
    </inertial>
    <visual>
      <origin
        xyz="0 0 0"
        rpy="0 0 0" />
      <geometry>
        <mesh
          filename="package://agv/meshes/rb_wheel.STL" />
      </geometry>
      <material
        name="">
        <color
          rgba="0.898039215686275 0.917647058823529 0.929411764705882 1" />
      </material>
    </visual>
    <collision>
      <origin
        xyz="0 0 0"
        rpy="0 0 0" />
      <geometry>
        <mesh
          filename="package://agv/meshes/rb_wheel.STL" />
      </geometry>
      <surface>
        <friction>
          <ode>
            <mu>0.1</mu>
            <mu2>0.1</mu2>
          </ode>
        </friction>
      </surface>
    </collision>
  </link>
  <joint
    name="rb_wheel_joint"
    type="continuous">
    <origin
      xyz="0.063772 0 0.02179"
      rpy="0 0 0" />
    <parent
      link="rb_castor" />
    <child
      link="rb_wheel" />
    <axis
      xyz="0 1 0" />
  </joint>
  <link
    name="lb_castor">
    <inertial>
      <origin
        xyz="-0.00517721936966276 0.00420937017066594 0.0380494601034228"
        rpy="0 0 0" />
      <mass
        value="0.308413228261502" />
      <inertia
        ixx="0.000176863120188544"
        ixy="-6.34833059557406E-13"
        ixz="6.18013671363662E-06"
        iyy="0.000219868353385142"
        iyz="1.64943821697838E-12"
        izz="0.000225039466125424" />
    </inertial>
    <visual>
      <origin
        xyz="0 0 0"
        rpy="0 0 0" />
      <geometry>
        <mesh
          filename="package://agv/meshes/lb_castor.STL" />
      </geometry>
      <material
        name="">
        <color
          rgba="0.752941176470588 0.752941176470588 0.752941176470588 1" />
      </material>
    </visual>
    <collision>
      <origin
        xyz="0 0 0"
        rpy="0 0 0" />
      <geometry>
        <mesh
          filename="package://agv/meshes/lb_castor.STL" />
      </geometry>
    </collision>
  </link>
  <joint
    name="lb_castor_joint"
    type="continuous">
    <origin
      xyz="-0.34885 0.19062 0.0745"
      rpy="0 0 0" />
    <parent
      link="base_link" />
    <child
      link="lb_castor" />
    <axis
      xyz="0 0 1" />
  </joint>
  <link
    name="lb_wheel">
    <inertial>
      <origin
        xyz="4.44089209850063E-16 0.00436655577999259 -5.68989300120393E-16"
        rpy="0 0 0" />
      <mass
        value="0.626468760963497" />
      <inertia
        ixx="0.000457310851286781"
        ixy="4.70677235448705E-18"
        ixz="4.20993572758698E-19"
        iyy="0.000807704367369124"
        iyz="-2.4396369467829E-18"
        izz="0.00045731085128678" />
    </inertial>
    <visual>
      <origin
        xyz="0 0 0"
        rpy="0 0 0" />
      <geometry>
        <mesh
          filename="package://agv/meshes/lb_wheel.STL" />
      </geometry>
      <material
        name="">
        <color
          rgba="0.898039215686275 0.917647058823529 0.929411764705882 1" />
      </material>
    </visual>
    <collision>
      <origin
        xyz="0 0 0"
        rpy="0 0 0" />
      <geometry>
        <mesh
          filename="package://agv/meshes/lb_wheel.STL" />
      </geometry>
      <surface>
        <friction>
          <ode>
            <mu>0.1</mu>
            <mu2>0.1</mu2>
          </ode>
        </friction>
      </surface>
    </collision>
  </link>
  <joint
    name="lb_wheel_joint"
    type="continuous">
    <origin
      xyz="0.057574 0 -0.024493"
      rpy="0 0 0" />
    <parent
      link="lb_castor" />
    <child
      link="lb_wheel" />
    <axis
      xyz="0 1 0" />
  </joint>
  <link
    name="right_drive_wheel">
    <inertial>
      <origin
        xyz="-3.54048652770273E-06 -0.031496291820899 -3.5696755096154E-06"
        rpy="0 0 0" />
      <mass
        value="2.78395683195572" />
      <inertia
        ixx="0.00913856636219792"
        ixy="1.805615946359E-07"
        ixz="-1.4776702564025E-07"
        iyy="0.0171771783201694"
        iyz="1.98685876624374E-07"
        izz="0.00913995386509266" />
    </inertial>
    <visual>
      <origin
        xyz="0 0 0"
        rpy="0 0 0" />
      <geometry>
        <mesh
          filename="package://agv/meshes/right_drive_wheel.STL" />
      </geometry>
      <material
        name="">
        <color
          rgba="0.898039215686275 0.917647058823529 0.929411764705882 1" />
      </material>
    </visual>
    <collision>
      <origin
        xyz="0 0 0"
        rpy="0 0 0" />
      <geometry>
        <mesh
          filename="package://agv/meshes/right_drive_wheel.STL" />
      </geometry>
      <surface>
        <friction>
          <ode>
            <mu>0.1</mu>
            <mu2>0.1</mu2>
          </ode>
        </friction>
      </surface>
    </collision>
  </link>
  <joint
    name="right_drive_wheel_joint"
    type="continuous">
    <origin
      xyz="0 -0.25399 0.1"
      rpy="0 0 0" />
    <parent
      link="base_link" />
    <child
      link="right_drive_wheel" />
    <axis
      xyz="0 1 0" />
  </joint>
  <link
    name="left_drive_wheel">
    <inertial>
      <origin
        xyz="-3.54048651584484E-06 0.0315037081310673 -3.56963982006686E-06"
        rpy="0 0 0" />
      <mass
        value="2.78395684403156" />
      <inertia
        ixx="0.00913856636356478"
        ixy="1.80561594635264E-07"
        ixz="-1.47767025641837E-07"
        iyy="0.0171771783219602"
        iyz="1.98687368947795E-07"
        izz="0.00913995386645953" />
    </inertial>
    <visual>
      <origin
        xyz="0 0 0"
        rpy="0 0 0" />
      <geometry>
        <mesh
          filename="package://agv/meshes/left_drive_wheel.STL" />
      </geometry>
      <material
        name="">
        <color
          rgba="0.898039215686275 0.917647058823529 0.929411764705882 1" />
      </material>
    </visual>
    <collision>
      <origin
        xyz="0 0 0"
        rpy="0 0 0" />
      <geometry>
        <mesh
          filename="package://agv/meshes/left_drive_wheel.STL" />
      </geometry>
      <surface>
        <friction>
          <ode>
            <mu>0.1</mu>
            <mu2>0.1</mu2>
          </ode>
        </friction>
      </surface>
    </collision>
  </link>
  <joint
    name="left_drive_wheel_joint"
    type="continuous">
    <origin
      xyz="0 0.25401 0.1"
      rpy="0 0 0" />
    <parent
      link="base_link" />
    <child
      link="left_drive_wheel" />
    <axis
      xyz="0 1 0" />
  </joint>
  <link
    name="front_laser">
    <inertial>
      <origin
        xyz="-0.0324139612087624 0.00199136296597092 -0.291979110525302"
        rpy="0 0 0" />
      <mass
        value="0.263290310369682" />
      <inertia
        ixx="0"
        ixy="0"
        ixz="0"
        iyy="0"
        iyz="0"
        izz="0" />
    </inertial>
    <visual>
      <origin
        xyz="0 0 0"
        rpy="0 0 0" />
      <geometry>
        <mesh
          filename="package://agv/meshes/front_laser.STL" />
      </geometry>
      <material
        name="">
        <color
          rgba="0.752941176470588 0.752941176470588 0.752941176470588 1" />
      </material>
    </visual>
    <collision>
      <origin
        xyz="0 0 0"
        rpy="0 0 0" />
      <geometry>
        <mesh
          filename="package://agv/meshes/front_laser.STL" />
      </geometry>
    </collision>
  </link>
  <joint
    name="front_laser_joint"
    type="fixed">
    <origin
      xyz="0.51272 0.016293 0.24738"
      rpy="0 0 0" />
    <parent
      link="base_link" />
    <child
      link="front_laser" />
    <axis
      xyz="0 0 0" />
  </joint>
  <link
    name="back_laser">
    <inertial>
      <origin
        xyz="0.0032065624406587 -9.51388205930283E-05 -0.0208001444882332"
        rpy="0 0 0" />
      <mass
        value="0.0423507164973708" />
      <inertia
        ixx="1.66292142022261E-05"
        ixy="1.6955563728476E-07"
        ixz="1.20779262414247E-07"
        iyy="1.40868095586287E-05"
        iyz="-1.25757841294358E-08"
        izz="2.92430350907846E-05" />
    </inertial>
    <visual>
      <origin
        xyz="0 0 0.03"
        rpy="0 0 0" />
      <geometry>
        <mesh
          filename="package://agv/meshes/back_laser.STL" />
      </geometry>
      <material
        name="">
        <color
          rgba="0.752941176470588 0.752941176470588 0.752941176470588 1" />
      </material>
    </visual>
    <collision>
      <origin
        xyz="0 0 0"
        rpy="0 0 0" />
      <geometry>
        <mesh
          filename="package://agv/meshes/back_laser.STL" />
      </geometry>
    </collision>
  </link>
  <joint
    name="back_laser_joint"
    type="fixed">
    <origin
      xyz="-0.442 1.4819E-05 0.075"
      rpy="-3.1416 0 -3.1416" />
    <parent
      link="base_link" />
    <child
      link="back_laser" />
    <axis
      xyz="0 0 0" />
  </joint>
  <link
    name="kinect_camera">
    <inertial>
      <origin
        xyz="0.0352733424750911 4.52827284281263E-05 -0.00855275224788477"
        rpy="0 0 0" />
      <mass
        value="0.658662598935648" />
      <inertia
        ixx="0.00298640086718296"
        ixy="-9.35635152177406E-07"
        ixz="-5.71424475805588E-06"
        iyy="0.000269653471825197"
        iyz="-4.36289562296306E-08"
        izz="0.00311136457626082" />
    </inertial>
    <visual>
      <origin
        xyz="0 0 0"
        rpy="0 0 0" />
      <geometry>
        <mesh
          filename="package://agv/meshes/kinect_camera.STL" />
      </geometry>
      <material
        name="">
        <color
          rgba="0.752941176470588 0.752941176470588 0.752941176470588 1" />
      </material>
    </visual>
    <collision>
      <origin
        xyz="0 0 0"
        rpy="0 0 0" />
      <geometry>
        <mesh
          filename="package://agv/meshes/kinect_camera.STL" />
      </geometry>
    </collision>
  </link>
  <joint
    name="kinect_camera_joint"
    type="fixed">
    <origin
      xyz="0.079826 0.00011741 0.534"
      rpy="0 0 0" />
    <parent
      link="base_link" />
    <child
      link="kinect_camera" />
    <axis
      xyz="0 0 0" />
    <limit
      lower="0"
      upper="0"
      effort="0"
      velocity="0" />
  </joint>
  <link
    name="imu_sensor">
    <inertial>
      <origin
        xyz="0.0244871413074496 -0.0159200000000003 0.00100000000000006"
        rpy="0 0 0" />
      <mass
        value="0.00309627738311325" />
      <inertia
        ixx="2.60213018270652E-07"
        ixy="5.07468567346599E-21"
        ixz="-3.46277889032628E-25"
        iyy="6.21076876297214E-07"
        iyz="9.01257585639137E-22"
        izz="8.7922570964579E-07" />
    </inertial>
    <visual>
      <origin
        xyz="0 0 0"
        rpy="0 0 0" />
      <geometry>
        <mesh
          filename="package://agv/meshes/imu_sensor.STL" />
      </geometry>
      <material
        name="">
        <color
          rgba="0.792156862745098 0.819607843137255 0.929411764705882 1" />
      </material>
    </visual>
    <collision>
      <origin
        xyz="0 0 0"
        rpy="0 0 0" />
      <geometry>
        <mesh
          filename="package://agv/meshes/imu_sensor.STL" />
      </geometry>
    </collision>
  </link>
  <joint
    name="imu_sensor_joint"
    type="fixed">
    <origin
      xyz="-0.03095 0.01592 0.48038"
      rpy="0 0 0" />
    <parent
      link="base_link" />
    <child
      link="imu_sensor" />
    <axis
      xyz="0 0 0" />
  </joint>

  <!-- Noise parameters based on published spec for Hokuyo laser
       achieving "+-30mm" accuracy at range < 10m.  A mean of 0.0m and
       stddev of 0.01m will put 99.7% of samples within 0.03m of the true
       reading. -->

  <gazebo reference="front_laser">
    <sensor type="ray" name="head_hokuyo_sensor">
      <pose>0 0 0 0 0 0</pose>
      <visualize>true</visualize>
      <update_rate>10</update_rate>
      <ray>
        <scan>
          <horizontal>
            <samples>720</samples>
            <resolution>1</resolution>
            <min_angle>-3.14</min_angle>
            <max_angle>3.14</max_angle>
          </horizontal>
        </scan>
        <range>
          <min>0.10</min>
          <max>30.0</max>
          <resolution>0.01</resolution>
        </range>
        <noise>
          <type>gaussian</type>
          <mean>0.0</mean>
          <stddev>0.01</stddev>
        </noise>
      </ray>
      <plugin name="gazebo_ros_head_hokuyo_controller" filename="libgazebo_ros_laser.so">
        <topicName>/front_laser_scan</topicName>
        <frameName>front_laser</frameName>
      </plugin>
    </sensor>
  </gazebo>

   <gazebo reference="back_laser">
    <sensor type="ray" name="head_hokuyo_sensor">
      <pose>0 0 0 0 0 0</pose>
      <visualize>true</visualize>
      <update_rate>10</update_rate>
      <ray>
        <scan>
          <horizontal>
            <samples>720</samples>
            <resolution>1</resolution>
            <min_angle>-1.570796</min_angle>
            <max_angle>1.570796</max_angle>
          </horizontal>
        </scan>
        <range>
          <min>0.10</min>
          <max>30.0</max>
          <resolution>0.01</resolution>
        </range>
        <noise>
          <type>gaussian</type>
          <mean>0.0</mean>
          <stddev>0.01</stddev>
        </noise>
      </ray>
      <plugin name="gazebo_ros_head_hokuyo_controller" filename="libgazebo_ros_laser.so">
        <topicName>/back_laser_scan</topicName>
        <frameName>back_laser</frameName>
      </plugin>
    </sensor>
  </gazebo>

    <gazebo>
      <plugin name="differential_drive_controller" filename="libgazebo_ros_diff_drive.so">
        <!-- Plugin update rate in Hz -->
        <updateRate>20</updateRate>
        <!-- Name of left joint, defaults to `left_joint` -->
        <leftJoint>left_drive_wheel_joint</leftJoint>
        <!-- Name of right joint, defaults to `right_joint` -->
        <rightJoint>right_drive_wheel_joint</rightJoint>
        <!-- The distance from the center of one wheel to the other, in meters, defaults to 0.34 m -->
        <wheelSeparation>0.389</wheelSeparation>
        <!-- Diameter of the wheels, in meters, defaults to 0.15 m -->
        <wheelDiameter>0.2</wheelDiameter>
        <!-- Wheel acceleration, in rad/s^2, defaults to 0.0 rad/s^2 -->
        <wheelAcceleration>1.0</wheelAcceleration>
        <!-- Maximum torque which the wheels can produce, in Nm, defaults to 5 Nm -->
        <wheelTorque>20</wheelTorque>
        <!-- Topic to receive geometry_msgs/Twist message commands, defaults to `cmd_vel` -->
        <commandTopic>cmd_vel</commandTopic>
        <!-- Topic to publish nav_msgs/Odometry messages, defaults to `odom` -->
        <odometryTopic>odom</odometryTopic>
        <!-- Odometry frame, defaults to `odom` -->
        <odometryFrame>odom</odometryFrame>
        <!-- Robot frame to calculate odometry from, defaults to `base_footprint` -->
        <robotBaseFrame>base_footprint</robotBaseFrame>
        <!-- Odometry source, 0 for ENCODER, 1 for WORLD, defaults to WORLD -->
        <odometrySource>1</odometrySource>
        <!-- Set to true to publish transforms for the wheel links, defaults to false -->
        <publishWheelTF>true</publishWheelTF>
        <!-- Set to true to publish transforms for the odometry, defaults to true -->
        <publishOdom>true</publishOdom>
        <!-- Set to true to publish sensor_msgs/JointState on /joint_states for the wheel joints, defaults to false -->
        <publishWheelJointState>true</publishWheelJointState>
        <!-- Set to true to swap right and left wheels, defaults to true -->
        <legacyMode>false</legacyMode>
      </plugin>
    </gazebo>

    <!-- Keep this zero, update_rate in the parent <sensor> tag
      will control the frame rate. -->
 <gazebo reference="kinect_camera">
    <sensor type="camera" name="camera1">
      <update_rate>30.0</update_rate>
      <camera name="head">
        <horizontal_fov>1.3962634</horizontal_fov>
        <image>
          <width>800</width>
          <height>800</height>
          <format>R8G8B8</format>
        </image>
        <clip>
          <near>0.02</near>
          <far>300</far>
        </clip>
        <noise>
          <type>gaussian</type>
          <!-- Noise is sampled independently per pixel on each frame.
               That pixel's noise value is added to each of its color
               channels, which at that point lie in the range [0,1]. -->
          <mean>0.0</mean>
          <stddev>0.007</stddev>
        </noise>
      </camera>
      <plugin name="camera_controller" filename="libgazebo_ros_camera.so">
        <alwaysOn>true</alwaysOn>
        <updateRate>0.0</updateRate>
        <cameraName>/camera1</cameraName>
        <imageTopicName>image_raw</imageTopicName>
        <cameraInfoTopicName>camera_info</cameraInfoTopicName>
        <frameName>kinect_camera</frameName>
        <hackBaseline>0.07</hackBaseline>
        <distortionK1>0.0</distortionK1>
        <distortionK2>0.0</distortionK2>
        <distortionK3>0.0</distortionK3>
        <distortionT1>0.0</distortionT1>
        <distortionT2>0.0</distortionT2>
      </plugin>
    </sensor>
  </gazebo>

  <gazebo reference="imu_sensor">
    <material>Gazebo/Green</material>
  </gazebo>

  <gazebo reference="kinect_camera">
    <material>Gazebo/Black</material>
  </gazebo>

  <gazebo reference="back_laser">
    <material>Gazebo/Black</material>
  </gazebo>

  <gazebo reference="front_laser">
    <material>Gazebo/Black</material>
  </gazebo>

  <gazebo reference="right_drive_wheel">
    <material>Gazebo/Yellow</material>
  </gazebo>

  <gazebo reference="left_drive_wheel">
    <material>Gazebo/Yellow</material>
  </gazebo>

  <gazebo reference="rb_castor">
    <material>Gazebo/Blue</material>
  </gazebo>

  <gazebo reference="lb_castor">
    <material>Gazebo/Blue</material>
  </gazebo>

  <gazebo reference="rf_castor">
    <material>Gazebo/Blue</material>
  </gazebo>

  <gazebo reference="lf_castor">
    <material>Gazebo/Blue</material>
  </gazebo>

  <gazebo reference="rb_wheel">
    <material>Gazebo/Yellow</material>
  </gazebo>

  <gazebo reference="lb_wheel">
    <material>Gazebo/Yellow</material>
  </gazebo>

  <gazebo reference="rf_wheel">
    <material>Gazebo/Yellow</material>
  </gazebo>

  <gazebo reference="lf_wheel">
    <material>Gazebo/Yellow</material>
  </gazebo>

  <gazebo reference="base_link">
    <material>Gazebo/Grey</material>
  </gazebo>

</robot>
